Workbook

Sheet About
A1: NexLearn Economic Balance Study — Batch 9
A2: How the numbers were produced and how to reproduce them
A4: Provenance
A5: Engine | B5: NexLearn V2 frozen economic engine (src/simulation). Diff against baseline commit 003f697: none
A6: Valuation model | B6: NXLN-VAL-1.0 (src/production/v2/insights/valuation.ts) — production implementation
A7: Executive scoring | B7: NXLN-EXEC-1.1 (src/production/v2/insights/executive.ts) — production implementation
A8: Terminal score | B8: scoreV2Company (src/simulation/engineV2Scoring.ts)
A9: Runner | B9: scripts/lab/batch9/runner.ts → Test Lab runArc (full eight-quarter arc: market path, Q4 commitment, Q5 contract, Q6 recession, Q7 crisis, Q8 final option, CFO liquidity forecast and financing)
A10: Repository commit | B10: 2d49f89
A11: Generated | B11: 2026-10-13T08:23:42.000Z
A12: Reproduce | B12: LAB_WRITE=1 npx vitest run scripts/lab/batch9/write.test.ts → docs/batch9/lab-results.json; python3 scripts/lab/batch9/build_workbook.py
A13: Verification | B13: npx vitest run scripts/lab/batch9/lab.test.ts — engine unchanged; lab results equal the production replay path (price, executive, terminal, cash) for all ten strategies; ledgers reconcile; overrides restored; re-based mixes are steady states
A15: Assumptions that apply to every run
A16: • All money in $M. Quarter 1 = Q1 2023; Q8 = Q4 2024. Starting company: revenue $200M (Consumer $140M, Enterprise $40M, University $16M, AI-native $4M), operating profit $30M, cash $60M.
A17: • Allocations are $30M per quarter (the strategic envelope); any unallocated amount is held as Cash Reserve. At Q8 the earned final option may raise the envelope to $45M (scale independently) or $60M (raise growth capital); the extra goes to the destination-aligned buckets (Test Lab policy).
A18: • Every strategy uses the same event policy (Test Lab DEFAULT_POLICY): accept the Q5 contract when on strategy and deliverable (fit ≥ 0.3) or fit ≥ 0.55; recession: hiring freeze when not investing in People, plus a targeted cut and $10M slower investment when cash < $40M; debt-first liquidity to keep closing cash ≥ $25M; crisis response by severity; Q8 option by eligibility. Differences between strategies therefore come from the investment strategy and destination.
A19: • Market: the engine’s market path is deterministic (one authored scenario). Sensitivity uses the runner’s supported market-override hook to vary conditions; player briefings (signals) stay as authored, so only the adaptive strategy could react to them. No stochastic outcomes were invented.
A20: • Executive scores (NXLN-EXEC-1.1) are reported only for runs that start from the production company, because the scoring compares against that starting company.
A21: • Starting-mix experiments change calibration constants in memory for one run and restore them afterwards (verified by test). Valuation for those runs is anchored on the production starting company; “price from own start” rescales to the experiment’s own Q0.
A22: • Allocation grid: every allocation of $30M in $5M steps across the six buckets (462 allocations) × five destinations = 2,310 eight-quarter runs.
A24: Strategy definitions
A25: Id | B25: Name | C25: Family | D25: Allocation (per quarter) | E25: Description
A26: consumer-led | B26: Consumer-led | C26: Consumer | D26: $20M Consumer + $10M People | E26: $20M Consumer + $10M People every quarter; commits to Consumer AI
A27: enterprise-led | B27: Enterprise-led | C27: Enterprise | D27: $20M Enterprise + $10M People | E27: $20M Enterprise + $10M People; commits to AI-powered Enterprise
A28: ai-led | B28: AI-led | C28: AI | D28: $20M AI/Product + $10M People | E28: $20M AI/Product + $10M People; commits to Premium Human + AI
A29: diversified | B29: Diversified | C29: Diversified | D29: $10M Consumer + $10M Enterprise + $10M AI | E29: $10M each Consumer, Enterprise, AI/Product; commits to Balanced Marketplace
A30: consumer-only | B30: Consumer-only | C30: Consumer | D30: $30M Consumer | E30: $30M Consumer; commits to Consumer AI
A31: enterprise-only | B31: Enterprise-only | C31: Enterprise | D31: $30M Enterprise | E31: $30M Enterprise; commits to AI-powered Enterprise
A32: ai-only | B32: AI-only | C32: AI | D32: $30M AI/Product | E32: $30M AI/Product; commits to Consumer AI
A33: university-led | B33: University-led | C33: University | D33: $20M University + $10M People | E33: $20M University/Credentials + $10M People; commits to University/Credential Infrastructure
A34: cash-preservation | B34: Cash preservation | C34: Cash | D34: $20M held in reserve; $4M Consumer, $3M Enterprise, $3M AI | E34: Invests $10M a quarter ($4M Consumer, $3M Enterprise, $3M AI/Product) and holds $20M in reserve; Balanced Marketplace
A35: adaptive | B35: Adaptive (evidence-responsive) | C35: Adaptive | D35: Balanced Q1, then shifts with market evidence (Test Lab "evidence-responsive") | E35: Explores broadly in Q1, then follows the evidence: shifts toward Enterprise + AI when AI disruption and enterprise AI demand appear, keeps Consumer defended, commits to AI-powered Enterprise at Q4.
A36: university-only | B36: University-only | C36: University | D36: $30M University | E36: $30M University/Credentials
... A39: enterprise-ai-people | B39: Enterprise + AI + People | C39: Enterprise | D39: $15M Enterprise + $10M AI + $5M People | E39: $15M Enterprise + $10M AI + $5M People
A41: Market scenarios (sensitivity)
A42: Id | B42: Label | C42: Definition
A43: authored | B43: Authored arc | C43: The production scenario: AI disruption from Q2, Q5 contract, Q6 recession, Q7 crisis, Q8 final decision.
A44: consumer-weak | B44: Consumer weaker | C44: Consumer demand ×0.9 and commoditization +0.15 from Q2.
A45: consumer-strong | B45: Consumer stronger | C45: Consumer demand ×1.1, commoditization halved and CAC pressure −0.1 from Q2.
A46: enterprise-boom | B46: Enterprise boom | C46: Enterprise demand ×1.2 and enterprise AI demand ×1.15 from Q2.
...

Sheet Executive comparison
A1: 1 · Executive comparison — Q8 (Q4 2024) outcomes
A2: Authored market, production starting company, identical event policy. Ranks and comparisons are formulas over the recorded results.
A4: Key findings
A5: • Consumer investment is not the dominant strategy. Consumer-only ranks 7th of 10 on Q8 share price and 8th on the terminal score, and sits at the 27th percentile of all 462 tested allocations. It is near the top only in Q1–Q2 (2nd–3rd, within $1 of the leader) and falls to 5th–7th from Q3.
A6: • AI/Product is the dominant investment. Every best allocation for every destination contains $10M AI/Product; the best allocation without AI scores $116–$133 against $156–$166 with it. An extra $10M a quarter in AI adds $25M of Q8 revenue versus $8M for Consumer.
A7: • Enterprise is not commercially viable as a lead strategy: Enterprise-only finishes last and Enterprise-led 9th in all ten market scenarios. Each extra $5M of Enterprise lowers the average Q8 price. University-led holds a $111 price but University revenue does not grow within eight quarters.
A8: • The strongest single play is Consumer + AI ($15M each, Consumer AI destination): $164.5 share price, 99th percentile. Consumer works as AI’s complement: it defends the 70% revenue base from the AI disruption (strategies without Consumer investment lose up to $19M of Consumer revenue by Q8), carries no recurring cost commitment and matures 50% in the quarter invested.
A10: Q8 outcomes by strategy
A11: Rows 1–10 are the required strategies; rows 11–14 are supplementary. Rank formulas rank the ten required strategies only.
A12: Strategy | B12: Family | C12: Allocation | D12: Destination | E12: Q8 revenue ($M) | F12: Q8 operating profit ($M) | G12: Cumulative OP Q1–Q8 ($M) | H12: Q8 cash ($M) | I12: Q8 debt ($M) | J12: Net cash ($M) | K12: Share price Q8 ($) | L12: Price change vs $100 | M12: Terminal score | N12: Financial | O12: Strategic | P12: Organizational | Q12: Executive team avg | R12: CEO | S12: CFO | T12: CPO | U12: CGO | V12: CPeO | W12: Culture Q8 | X12: Capability gain (pts) | Y12: Financing raised ($M) | Z12: Ever insolvent | AA12: Distressed quarters | AB12: Q8 option | AC12: Q5 contract | AD12: Grid percentile (price) | AE12: Rank: price | AF12: Rank: terminal | AG12: Rank: cumulative OP
A13: Consumer-led | B13: Consumer | C13: $20M Consumer + $10M People | D13: consumer-ai | E13: 212.37071 | F13: 34.530189 | G13: 249.95285 | H13: 46.64691 | I13: 0 | J13: =H13-I13 -> 46.64691 | K13: 116.21624 | L13: =K13/100-1 -> 0.16216236 | M13: 68.063016 | N13: 58.235331 | O13: 73.450224 | P13: 76.245222 | Q13: 64.156937 | R13: 71.793564 | S13: 62.586796 | T13: 59.516852 | U13: 61.344226 | V13: 65.543247 | W13: 72 | X13: 111.04223 | Y13: 0 | Z13: no | AA13: 0 | AB13: scale-independently | AC13: declined | AD13: 0.37445887 | AE13: =RANK(K13,$K$13:$K$22) -> 5 | AF13: =RANK(M13,$M$13:$M$22) -> 5 | AG13: =RANK(G13,$G$13:$G$22) -> 6
A14: Enterprise-led | B14: Enterprise | C14: $20M Enterprise + $10M People | D14: enterprise-ai | E14: 197.52408 | F14: 23.305665 | G14: 199.8321 | H14: 25 | I14: 0.065865433 | J14: =H14-I14 -> 24.934135 | K14: 81.785813 | L14: =K14/100-1 -> -0.18214187 | M14: 58.631732 | N14: 49.065257 | O14: 63.716497 | P14: 66.819419 | Q14: 48.887657 | R14: 60.969206 | S14: 40.557897 | T14: 48.551279 | U14: 43.259555 | V14: 51.100351 | W14: 63 | X14: 137.08348 | Y14: 0.065865433 | Z14: no | AA14: 0 | AB14: continue | AC14: accepted | AD14: 0.067099567 | AE14: =RANK(K14,$K$13:$K$22) -> 9 | AF14: =RANK(M14,$M$13:$M$22) -> 9 | AG14: =RANK(G14,$G$13:$G$22) -> 9
A15: AI-led | B15: AI | C15: $20M AI/Product + $10M People | D15: premium-human-ai | E15: 234.70009 | F15: 45.626067 | G15: 277.75757 | H15: 84.507569 | I15: 0 | J15: =H15-I15 -> 84.507569 | K15: 148.51302 | L15: =K15/100-1 -> 0.48513019 | M15: 80.49111 | N15: 77.675411 | O15: 87.169104 | P15: 75.647035 | Q15: 73.502476 | R15: 78.659525 | S15: 74.380816 | T15: 80.373536 | U15: 65.137403 | V15: 68.961101 | W15: 67.705829 | X15: 134.07519 | Y15: 0 | Z15: no | AA15: 0 | AB15: scale-independently | AC15: declined | AD15: 0.80952381 | AE15: =RANK(K15,$K$13:$K$22) -> 2 | AF15: =RANK(M15,$M$13:$M$22) -> 1 | AG15: =RANK(G15,$G$13:$G$22) -> 1
A16: Diversified | B16: Diversified | C16: $10M Consumer + $10M Enterprise + $10M AI | D16: balanced-marketplace | E16: 226.21999 | F16: 46.040358 | G16: 273.094 | H16: 76.420295 | I16: 0 | J16: =H16-I16 -> 76.420295 | K16: 143.75331 | L16: =K16/100-1 -> 0.43753309 | M16: 76.715858 | N16: 75.13875 | O16: 92.817875 | P16: 56.696408 | Q16: 72.310093 | R16: 82.728366 | S16: 73.919518 | T16: 72.727674 | U16: 68.700898 | V16: 63.474009 | W16: 69.451645 | X16: 194.49002 | Y16: 0 | Z16: no | AA16: 0 | AB16: scale-independently | AC16: declined | AD16: 0.91991342 | AE16: =RANK(K16,$K$13:$K$22) -> 3 | AF16: =RANK(M16,$M$13:$M$22) -> 3 | AG16: =RANK(G16,$G$13:$G$22) -> 2
A17: Consumer-only | B17: Consumer | C17: $30M Consumer | D17: consumer-ai | E17: 203.89316 | F17: 34.747534 | G17: 257.07733 | H17: 56.391335 | I17: 0 | J17: =H17-I17 -> 56.391335 | K17: 109.88221 | L17: =K17/100-1 -> 0.09882212 | M17: 61.803585 | N17: 56.212526 | O17: 71.610483 | P17: 57.019623 | Q17: 58.563156 | R17: 66.165319 | S17: 62.979138 | T17: 52.390534 | U17: 54.515532 | V17: 56.765256 | W17: 70.5 | X17: 65.380066 | Y17: 0 | Z17: no | AA17: 0 | AB17: scale-independently | AC17: declined | AD17: 0.26623377 | AE17: =RANK(K17,$K$13:$K$22) -> 7 | AF17: =RANK(M17,$M$13:$M$22) -> 8 | AG17: =RANK(G17,$G$13:$G$22) -> 5
A18: Enterprise-only | B18: Enterprise | C18: $30M Enterprise | D18: enterprise-ai | E18: 193.27843 | F18: 22.33508 | G18: 196.9351 | H18: 25 | I18: 26.681658 | J18: =H18-I18 -> -1.681658 | K18: 74.746025 | L18: =K18/100-1 -> -0.25253975 | M18: 51.717494 | N18: 45.532497 | O18: 62.658737 | P18: 46.295749 | Q18: 43.022401 | R18: 56.697788 | S18: 37.552587 | T18: 42.437175 | U18: 38.913459 | V18: 39.510998 | W18: 61.5 | X18: 106.25718 | Y18: 26.681658 | Z18: no | AA18: 0 | AB18: continue | AC18: accepted | AD18: 0.025974026 | AE18: =RANK(K18,$K$13:$K$22) -> 10 | AF18: =RANK(M18,$M$13:$M$22) -> 10 | AG18: =RANK(G18,$G$13:$G$22) -> 10
A19: AI-only | B19: AI | C19: $30M AI/Product | D19: consumer-ai | E19: 220.94389 | F19: 38.982539 | G19: 258.24927 | H19: 60.269426 | I19: 0 | J19: =H19-I19 -> 60.269426 | K19: 127.25922 | L19: =K19/100-1 -> 0.2725922 | M19: 69.260958 | N19: 68.303905 | O19: 78.869453 | P19: 57.340351 | Q19: 65.800633 | R19: 77.72633 | S19: 66.623965 | T19: 72.797273 | U19: 51.106466 | V19: 60.749132 | W19: 70.5 | X19: 111.73026 | Y19: 0 | Z19: no | AA19: 0 | AB19: scale-independently | AC19: declined | AD19: 0.49134199 | AE19: =RANK(K19,$K$13:$K$22) -> 4 | AF19: =RANK(M19,$M$13:$M$22) -> 4 | AG19: =RANK(G19,$G$13:$G$22) -> 4
A20: University-led | B20: University | C20: $20M University + $10M People | D20: university-infrastructure | E20: 198.16419 | F20: 24.703897 | G20: 214.01273 | H20: 32.512726 | I20: 0 | J20: =H20-I20 -> 32.512726 | K20: 110.90344 | L20: =K20/100-1 -> 0.10903443 | M20: 63.653293 | N20: 48.961507 | O20: 67.197319 | P20: 82.198515 | Q20: 59.681153 | R20: 68.650174 | S20: 51.596176 | T20: 62.646879 | U20: 52.981846 | V20: 62.530689 | W20: 72 | X20: 125 | Y20: 0 | Z20: no | AA20: 0 | AB20: continue | AC20: declined | AD20: 0.28354978 | AE20: =RANK(K20,$K$13:$K$22) -> 6 | AF20: =RANK(M20,$M$13:$M$22) -> 7 | AG20: =RANK(G20,$G$13:$G$22) -> 8
A21: Cash preservation | B21: Cash | C21: $20M held in reserve; $4M Consumer, $3M Enterprise, $3M AI | D21: balanced-marketplace | E21: 196.35179 | F21: 28.102658 | G21: 223.16578 | H21: 186.7938 | I21: 0 | J21: =H21-I21 -> 186.7938 | K21: 102.81459 | L21: =K21/100-1 -> 0.028145919 | M21: 64.43345 | N21: 61.553448 | O21: 73.119733 | P21: 56.880657 | Q21: 55.27048 | R21: 63.527144 | S21: 55.429968 | T21: 57.889601 | U21: 46.482422 | V21: 53.023263 | W21: 69.524057 | X21: 84.84047 | Y21: 0 | Z21: no | AA21: 0 | AB21: scale-independently | AC21: declined | AD21: n/a (not a constant $5M-step allocation) | AE21: =RANK(K21,$K$13:$K$22) -> 8 | AF21: =RANK(M21,$M$13:$M$22) -> 6 | AG21: =RANK(G21,$G$13:$G$22) -> 7
A22: Adaptive (evidence-responsive) | B22: Adaptive | C22: Balanced Q1, then shifts with market evidence (Test Lab "evidence-responsive") | D22: enterprise-ai | E22: 233.34923 | F22: 47.053928 | G22: 262.125 | H22: 80.90442 | I22: 0 | J22: =H22-I22 -> 80.90442 | K22: 148.82113 | L22: =K22/100-1 -> 0.48821127 | M22: 80.331139 | N22: 79.924649 | O22: 86.873244 | P22: 71.822576 | Q22: 76.139336 | R22: 86.384888 | S22: 73.04494 | T22: 75.574488 | U22: 71.551872 | V22: 74.140492 | W22: 72 | X22: 197.82665 | Y22: 0 | Z22: no | AA22: 0 | AB22: scale-independently | AC22: accepted | AD22: n/a (not a constant $5M-step allocation) | AE22: =RANK(K22,$K$13:$K$22) -> 1 | AF22: =RANK(M22,$M$13:$M$22) -> 2 | AG22: =RANK(G22,$G$13:$G$22) -> 3
A23: University-only | B23: University | C23: $30M University | D23: university-infrastructure | E23: 190.77351 | F23: 25.150063 | G23: 218.92204 | H23: 37.422041 | I23: 0 | J23: =H23-I23 -> 37.422041 | K23: 111.10786 | L23: =K23/100-1 -> 0.11107862 | M23: 60.884119 | N23: 47.227856 | O23: 73.981225 | P23: 64.398192 | Q23: 55.904334 | R23: 64.537132 | S23: 54.901946 | T23: 58.024164 | U23: 48.30228 | V23: 53.756149 | W23: 70.5 | X23: 78.5 | Y23: 0 | Z23: no | AA23: 0 | AB23: scale-independently | AC23: declined | AD23: 0.29004329
A24: Consumer + AI | B24: Consumer | C24: $15M Consumer + $15M AI | D24: consumer-ai | E24: 241.53032 | F24: 57.949347 | G24: 312.17064 | H24: 110.77155 | I24: 0 | J24: =H24-I24 -> 110.77155 | K24: 164.53244 | L24: =K24/100-1 -> 0.64532435 | M24: 81.593225 | N24: 85.668892 | O24: 94.230801 | P24: 57.379552 | Q24: 79.727188 | R24: 89.237723 | S24: 85.340108 | T24: 78.512012 | U24: 76.681307 | V24: 68.864792 | W24: 70.5 | X24: 168.37958 | Y24: 0 | Z24: no | AA24: 0 | AB24: scale-independently | AC24: declined | AD24: 0.99134199
A25: Enterprise + AI | B25: Enterprise | C25: $15M Enterprise + $15M AI | D25: enterprise-ai | E25: 229.37912 | F25: 43.642821 | G25: 254.01798 | H25: 44.339872 | I25: 0 | J25: =H25-I25 -> 44.339872 | K25: 145.25432 | L25: =K25/100-1 -> 0.45254318 | M25: 75.013205 | N25: 74.429964 | O25: 88.374826 | P25: 57.240123 | Q25: 71.297265 | R25: 84.257367 | S25: 70.54433 | T25: 73.128111 | U25: 63.954127 | V25: 64.602389 | W25: 70.5 | X25: 216.79854 | Y25: 0 | Z25: no | AA25: 0 | AB25: scale-independently | AC25: accepted | AD25: 0.75324675
A26: Enterprise + AI + People | B26: Enterprise | C26: $15M Enterprise + $10M AI + $5M People | D26: enterprise-ai | E26: 233.40985 | F26: 44.191944 | G26: 252.58351 | H26: 43.096898 | I26: 0 | J26: =H26-I26 -> 43.096898 | K26: 148.26927 | L26: =K26/100-1 -> 0.48269272 | M26: 79.145913 | N26: 76.224108 | O26: 87.909911 | P26: 71.551201 | Q26: 74.922014 | R26: 87.135568 | S26: 70.802094 | T26: 75.92673 | U26: 67.362364 | V26: 73.383311 | W26: 72 | X26: 224.50146 | Y26: 0 | Z26: no | AA26: 0 | AB26: scale-independently | AC26: accepted | AD26: 0.8030303
A28: Does Consumer-only outperform most alternatives? (formulas over the table above)
A29: Required strategies with a lower Q8 share price than Consumer-only | E29: =COUNTIF($K$13:$K$22,"<"&K17) -> 3
A30: … with a lower terminal score | E30: =COUNTIF($M$13:$M$22,"<"&M17) -> 2
A31: … with lower Q8 revenue | E31: =COUNTIF($E$13:$E$22,"<"&E17) -> 4
A32: … with lower cumulative operating profit | E32: =COUNTIF($G$13:$G$22,"<"&G17) -> 5
A33: Consumer-only price gap to the best required strategy ($) | E33: =K17-MAX($K$13:$K$22) -> -38.938915
A34: Spread of Q8 share price across required strategies ($) | E34: =MAX($K$13:$K$22)-MIN($K$13:$K$22) -> 74.075101
A35: Out of 9 alternatives. Consumer-only beats only Enterprise-led, Enterprise-only and (on price) Cash preservation.

Sheet Quarter-by-quarter results
A1: 2 · Quarter-by-quarter results
A2: Every quarter of every strategy (authored market). Matrices at the right are SUMIFS formulas over the long table.
A4: Strategy | B4: Q | C4: Revenue | D4: Consumer | E4: Enterprise | F4: University | G4: AI-native | H4: Operating profit | I4: Margin | J4: Strategic investment | K4: Event costs | L4: Financing | M4: Cash | N4: Debt | O4: Share price | P4: Culture | Q4: Org capacity | R4: Load ÷ capacity | S4: Solvency | T4: Distressed | V4: Revenue ($M)
A5: Consumer-led | B5: 1 | C5: 200.28931 | D5: 140.28616 | E5: 40 | F5: 15.99968 | G5: 4.003465 | H5: 30.215882 | I5: =IF(C5=0,0,H5/C5) -> 0.15086118 | J5: 30 | K5: 0 | L5: 0 | M5: 60.215882 | N5: 0 | O5: 100.6919 | P5: 72 | Q5: 62.8875 | R5: 0.4293381 | S5: healthy | T5: no | V5: Strategy | W5: Q1 | X5: Q2 | Y5: Q3 | Z5: Q4 | AA5: Q5 | AB5: Q6 | AC5: Q7 | AD5: Q8
A6: Consumer-led | B6: 2 | C6: 199.52648 | D6: 139.2281 | E6: 40.000545 | F6: 15.998792 | G6: 4.2990379 | H6: 29.693849 | I6: =IF(C6=0,0,H6/C6) -> 0.1488216 | J6: 30 | K6: 0 | L6: 0 | M6: 59.90973 | N6: 0 | O6: 99.941385 | P6: 72 | Q6: 67.811746 | R6: 0.39816111 | S6: healthy | T6: no | V6: Consumer-led | W6: =SUMIFS($C$5:$C$116,$A$5:$A$116,$V6,$B$5:$B$116,1) -> 200.28931 | X6: =SUMIFS($C$5:$C$116,$A$5:$A$116,$V6,$B$5:$B$116,2) -> 199.52648 | Y6: =SUMIFS($C$5:$C$116,$A$5:$A$116,$V6,$B$5:$B$116,3) -> 199.72808 | Z6: =SUMIFS($C$5:$C$116,$A$5:$A$116,$V6,$B$5:$B$116,4) -> 201.43358 | AA6: =SUMIFS($C$5:$C$116,$A$5:$A$116,$V6,$B$5:$B$116,5) -> 205.0317 | AB6: =SUMIFS($C$5:$C$116,$A$5:$A$116,$V6,$B$5:$B$116,6) -> 207.6048 | AC6: =SUMIFS($C$5:$C$116,$A$5:$A$116,$V6,$B$5:$B$116,7) -> 207.60835 | AD6: =SUMIFS($C$5:$C$116,$A$5:$A$116,$V6,$B$5:$B$116,8) -> 212.37071
A7: Consumer-led | B7: 3 | C7: 199.72808 | D7: 139.25373 | E7: 40.004778 | F7: 15.997945 | G7: 4.4716251 | H7: 28.946941 | I7: =IF(C7=0,0,H7/C7) -> 0.14493176 | J7: 30 | K7: 0 | L7: 0 | M7: 58.856671 | N7: 0 | O7: 101.91184 | P7: 72 | Q7: 73.636473 | R7: 0.36666612 | S7: healthy | T7: no | V7: Enterprise-led | W7: =SUMIFS($C$5:$C$116,$A$5:$A$116,$V7,$B$5:$B$116,1) -> 200.07623 | X7: =SUMIFS($C$5:$C$116,$A$5:$A$116,$V7,$B$5:$B$116,2) -> 198.70147 | Y7: =SUMIFS($C$5:$C$116,$A$5:$A$116,$V7,$B$5:$B$116,3) -> 197.69015 | Z7: =SUMIFS($C$5:$C$116,$A$5:$A$116,$V7,$B$5:$B$116,4) -> 197.12706 | AA7: =SUMIFS($C$5:$C$116,$A$5:$A$116,$V7,$B$5:$B$116,5) -> 197.13144 | AB7: =SUMIFS($C$5:$C$116,$A$5:$A$116,$V7,$B$5:$B$116,6) -> 198.03997 | AC7: =SUMIFS($C$5:$C$116,$A$5:$A$116,$V7,$B$5:$B$116,7) -> 196.09153 | AD7: =SUMIFS($C$5:$C$116,$A$5:$A$116,$V7,$B$5:$B$116,8) -> 197.52408
A8: Consumer-led | B8: 4 | C8: 201.43358 | D8: 140.77214 | E8: 40.028187 | F8: 15.996736 | G8: 4.6365162 | H8: 29.501711 | I8: =IF(C8=0,0,H8/C8) -> 0.14645875 | J8: 30 | K8: 0 | L8: 0 | M8: 58.358382 | N8: 0 | O8: 106.80956 | P8: 72 | Q8: 79.452458 | R8: 0.40578859 | S8: healthy | T8: no | V8: AI-led | W8: =SUMIFS($C$5:$C$116,$A$5:$A$116,$V8,$B$5:$B$116,1) -> 200.06993 | X8: =SUMIFS($C$5:$C$116,$A$5:$A$116,$V8,$B$5:$B$116,2) -> 199.73857 | Y8: =SUMIFS($C$5:$C$116,$A$5:$A$116,$V8,$B$5:$B$116,3) -> 202.03069 | Z8: =SUMIFS($C$5:$C$116,$A$5:$A$116,$V8,$B$5:$B$116,4) -> 207.59878 | AA8: =SUMIFS($C$5:$C$116,$A$5:$A$116,$V8,$B$5:$B$116,5) -> 215.29644 | AB8: =SUMIFS($C$5:$C$116,$A$5:$A$116,$V8,$B$5:$B$116,6) -> 220.84267 | AC8: =SUMIFS($C$5:$C$116,$A$5:$A$116,$V8,$B$5:$B$116,7) -> 224.97777 | AD8: =SUMIFS($C$5:$C$116,$A$5:$A$116,$V8,$B$5:$B$116,8) -> 234.70009
A9: Consumer-led | B9: 5 | C9: 205.0317 | D9: 144.22209 | E9: 40.052521 | F9: 15.993013 | G9: 4.764075 | H9: 31.444173 | I9: =IF(C9=0,0,H9/C9) -> 0.1533625 | J9: 30 | K9: 0 | L9: 0 | M9: 59.802555 | N9: 0 | O9: 112.37178 | P9: 72 | Q9: 85.288105 | R9: 0.36629846 | S9: healthy | T9: no | V9: Diversified | W9: =SUMIFS($C$5:$C$116,$A$5:$A$116,$V9,$B$5:$B$116,1) -> 200.14854 | X9: =SUMIFS($C$5:$C$116,$A$5:$A$116,$V9,$B$5:$B$116,2) -> 199.16879 | Y9: =SUMIFS($C$5:$C$116,$A$5:$A$116,$V9,$B$5:$B$116,3) -> 199.76185 | Z9: =SUMIFS($C$5:$C$116,$A$5:$A$116,$V9,$B$5:$B$116,4) -> 202.6907 | AA9: =SUMIFS($C$5:$C$116,$A$5:$A$116,$V9,$B$5:$B$116,5) -> 207.92077 | AB9: =SUMIFS($C$5:$C$116,$A$5:$A$116,$V9,$B$5:$B$116,6) -> 211.85648 | AC9: =SUMIFS($C$5:$C$116,$A$5:$A$116,$V9,$B$5:$B$116,7) -> 217.20149 | AD9: =SUMIFS($C$5:$C$116,$A$5:$A$116,$V9,$B$5:$B$116,8) -> 226.21999
A10: Consumer-led | B10: 6 | C10: 207.6048 | D10: 147.01072 | E10: 39.834299 | F10: 15.973898 | G10: 4.7858809 | H10: 33.507525 | I10: =IF(C10=0,0,H10/C10) -> 0.16140053 | J10: 30 | K10: 0 | L10: 0 | M10: 63.31008 | N10: 0 | O10: 113.45071 | P10: 72 | Q10: 91.16675 | R10: 0.33230809 | S10: healthy | T10: no | V10: Consumer-only | W10: =SUMIFS($C$5:$C$116,$A$5:$A$116,$V10,$B$5:$B$116,1) -> 200.27087 | X10: =SUMIFS($C$5:$C$116,$A$5:$A$116,$V10,$B$5:$B$116,2) -> 199.34345 | Y10: =SUMIFS($C$5:$C$116,$A$5:$A$116,$V10,$B$5:$B$116,3) -> 199.23324 | Z10: =SUMIFS($C$5:$C$116,$A$5:$A$116,$V10,$B$5:$B$116,4) -> 200.49999 | AA10: =SUMIFS($C$5:$C$116,$A$5:$A$116,$V10,$B$5:$B$116,5) -> 203.00558 | AB10: =SUMIFS($C$5:$C$116,$A$5:$A$116,$V10,$B$5:$B$116,6) -> 203.93292 | AC10: =SUMIFS($C$5:$C$116,$A$5:$A$116,$V10,$B$5:$B$116,7) -> 201.64853 | AD10: =SUMIFS($C$5:$C$116,$A$5:$A$116,$V10,$B$5:$B$116,8) -> 203.89316
A11: Consumer-led | B11: 7 | C11: 207.60835 | D11: 147.10896 | E11: 39.682619 | F11: 15.941963 | G11: 4.8748069 | H11: 32.112579 | I11: =IF(C11=0,0,H11/C11) -> 0.15467865 | J11: 30 | K11: 12.055938 | L11: 0 | M11: 53.366721 | N11: 0 | O11: 108.28464 | P11: 72 | Q11: 97.086766 | R11: 0.31930202 | S11: healthy | T11: no | V11: Enterprise-only | W11: =SUMIFS($C$5:$C$116,$A$5:$A$116,$V11,$B$5:$B$116,1) -> 200.02084 | X11: =SUMIFS($C$5:$C$116,$A$5:$A$116,$V11,$B$5:$B$116,2) -> 198.38635 | Y11: =SUMIFS($C$5:$C$116,$A$5:$A$116,$V11,$B$5:$B$116,3) -> 196.89297 | Z11: =SUMIFS($C$5:$C$116,$A$5:$A$116,$V11,$B$5:$B$116,4) -> 195.63305 | AA11: =SUMIFS($C$5:$C$116,$A$5:$A$116,$V11,$B$5:$B$116,5) -> 194.7803 | AB11: =SUMIFS($C$5:$C$116,$A$5:$A$116,$V11,$B$5:$B$116,6) -> 194.93357 | AC11: =SUMIFS($C$5:$C$116,$A$5:$A$116,$V11,$B$5:$B$116,7) -> 192.33649 | AD11: =SUMIFS($C$5:$C$116,$A$5:$A$116,$V11,$B$5:$B$116,8) -> 193.27843
A12: Consumer-led | B12: 8 | C12: 212.37071 | D12: 151.88496 | E12: 39.542181 | F12: 15.905861 | G12: 5.0377074 | H12: 34.530189 | I12: =IF(C12=0,0,H12/C12) -> 0.16259393 | J12: 41.25 | K12: 0 | L12: 0 | M12: 46.64691 | N12: 0 | O12: 116.21624 | P12: 72 | Q12: 100 | R12: 0.32 | S12: healthy | T12: no | V12: AI-only | W12: =SUMIFS($C$5:$C$116,$A$5:$A$116,$V12,$B$5:$B$116,1) -> 200.01771 | X12: =SUMIFS($C$5:$C$116,$A$5:$A$116,$V12,$B$5:$B$116,2) -> 199.64951 | Y12: =SUMIFS($C$5:$C$116,$A$5:$A$116,$V12,$B$5:$B$116,3) -> 201.46375 | Z12: =SUMIFS($C$5:$C$116,$A$5:$A$116,$V12,$B$5:$B$116,4) -> 205.48122 | AA12: =SUMIFS($C$5:$C$116,$A$5:$A$116,$V12,$B$5:$B$116,5) -> 210.86212 | AB12: =SUMIFS($C$5:$C$116,$A$5:$A$116,$V12,$B$5:$B$116,6) -> 213.473 | AC12: =SUMIFS($C$5:$C$116,$A$5:$A$116,$V12,$B$5:$B$116,7) -> 214.95644 | AD12: =SUMIFS($C$5:$C$116,$A$5:$A$116,$V12,$B$5:$B$116,8) -> 220.94389
A13: Enterprise-led | B13: 1 | C13: 200.07623 | D13: 140.03908 | E13: 40.033979 | F13: 15.99968 | G13: 4.003495 | H13: 30.05901 | I13: =IF(C13=0,0,H13/C13) -> 0.15023779 | J13: 30 | K13: 0 | L13: 0 | M13: 60.05901 | N13: 0 | O13: 100.19621 | P13: 72 | Q13: 62.9125 | R13: 0.39737731 | S13: healthy | T13: no | V13: University-led | W13: =SUMIFS($C$5:$C$116,$A$5:$A$116,$V13,$B$5:$B$116,1) -> 200.06279 | X13: =SUMIFS($C$5:$C$116,$A$5:$A$116,$V13,$B$5:$B$116,2) -> 198.6582 | Y13: =SUMIFS($C$5:$C$116,$A$5:$A$116,$V13,$B$5:$B$116,3) -> 197.69958 | Z13: =SUMIFS($C$5:$C$116,$A$5:$A$116,$V13,$B$5:$B$116,4) -> 197.41359 | AA13: =SUMIFS($C$5:$C$116,$A$5:$A$116,$V13,$B$5:$B$116,5) -> 197.97951 | AB13: =SUMIFS($C$5:$C$116,$A$5:$A$116,$V13,$B$5:$B$116,6) -> 197.07738 | AC13: =SUMIFS($C$5:$C$116,$A$5:$A$116,$V13,$B$5:$B$116,7) -> 195.91267 | AD13: =SUMIFS($C$5:$C$116,$A$5:$A$116,$V13,$B$5:$B$116,8) -> 198.16419
A14: Enterprise-led | B14: 2 | C14: 198.70147 | D14: 138.23939 | E14: 40.164087 | F14: 15.998792 | G14: 4.2992004 | H14: 28.298153 | I14: =IF(C14=0,0,H14/C14) -> 0.14241542 | J14: 30 | K14: 0 | L14: 0 | M14: 58.357163 | N14: 0 | O14: 97.565656 | P14: 72 | Q14: 67.878217 | R14: 0.36830667 | S14: healthy | T14: no | V14: Cash preservation | W14: =SUMIFS($C$5:$C$116,$A$5:$A$116,$V14,$B$5:$B$116,1) -> 200.05474 | X14: =SUMIFS($C$5:$C$116,$A$5:$A$116,$V14,$B$5:$B$116,2) -> 198.49466 | Y14: =SUMIFS($C$5:$C$116,$A$5:$A$116,$V14,$B$5:$B$116,3) -> 197.26972 | Z14: =SUMIFS($C$5:$C$116,$A$5:$A$116,$V14,$B$5:$B$116,4) -> 196.61118 | AA14: =SUMIFS($C$5:$C$116,$A$5:$A$116,$V14,$B$5:$B$116,5) -> 196.71866 | AB14: =SUMIFS($C$5:$C$116,$A$5:$A$116,$V14,$B$5:$B$116,6) -> 195.06402 | AC14: =SUMIFS($C$5:$C$116,$A$5:$A$116,$V14,$B$5:$B$116,7) -> 194.18132 | AD14: =SUMIFS($C$5:$C$116,$A$5:$A$116,$V14,$B$5:$B$116,8) -> 196.35179
A15: Enterprise-led | B15: 3 | C15: 197.69015 | D15: 136.77097 | E15: 40.44927 | F15: 15.997945 | G15: 4.4719671 | H15: 25.852616 | I15: =IF(C15=0,0,H15/C15) -> 0.13077341 | J15: 30 | K15: 0 | L15: 0 | M15: 54.209779 | N15: 0 | O15: 96.937106 | P15: 72 | Q15: 73.749614 | R15: 0.33898483 | S15: healthy | T15: no | V15: Adaptive (evidence-responsive) | W15: =SUMIFS($C$5:$C$116,$A$5:$A$116,$V15,$B$5:$B$116,1) -> 200.09855 | X15: =SUMIFS($C$5:$C$116,$A$5:$A$116,$V15,$B$5:$B$116,2) -> 198.93269 | Y15: =SUMIFS($C$5:$C$116,$A$5:$A$116,$V15,$B$5:$B$116,3) -> 198.95628 | Z15: =SUMIFS($C$5:$C$116,$A$5:$A$116,$V15,$B$5:$B$116,4) -> 201.05157 | AA15: =SUMIFS($C$5:$C$116,$A$5:$A$116,$V15,$B$5:$B$116,5) -> 205.30529 | AB15: =SUMIFS($C$5:$C$116,$A$5:$A$116,$V15,$B$5:$B$116,6) -> 211.75932 | AC15: =SUMIFS($C$5:$C$116,$A$5:$A$116,$V15,$B$5:$B$116,7) -> 221.27191 | AD15: =SUMIFS($C$5:$C$116,$A$5:$A$116,$V15,$B$5:$B$116,8) -> 233.34923
A16: Enterprise-led | B16: 4 | C16: 197.12706 | D16: 135.52456 | E16: 40.968835 | F16: 15.996736 | G16: 4.6369301 | H16: 23.900445 | I16: =IF(C16=0,0,H16/C16) -> 0.12124386 | J16: 30 | K16: 0 | L16: 0 | M16: 48.110224 | N16: 0 | O16: 95.293269 | P16: 72 | Q16: 79.58108 | R16: 0.4148788 | S16: healthy | T16: no | V16: University-only | W16: =SUMIFS($C$5:$C$116,$A$5:$A$116,$V16,$B$5:$B$116,1) -> 199.99582 | X16: =SUMIFS($C$5:$C$116,$A$5:$A$116,$V16,$B$5:$B$116,2) -> 198.28719 | Y16: =SUMIFS($C$5:$C$116,$A$5:$A$116,$V16,$B$5:$B$116,3) -> 196.75593 | Z16: =SUMIFS($C$5:$C$116,$A$5:$A$116,$V16,$B$5:$B$116,4) -> 195.6407 | AA16: =SUMIFS($C$5:$C$116,$A$5:$A$116,$V16,$B$5:$B$116,5) -> 195.15635 | AB16: =SUMIFS($C$5:$C$116,$A$5:$A$116,$V16,$B$5:$B$116,6) -> 193.04755 | AC16: =SUMIFS($C$5:$C$116,$A$5:$A$116,$V16,$B$5:$B$116,7) -> 190.26812 | AD16: =SUMIFS($C$5:$C$116,$A$5:$A$116,$V16,$B$5:$B$116,8) -> 190.77351
A17: Enterprise-led | B17: 5 | C17: 197.13144 | D17: 134.53598 | E17: 41.838088 | F17: 15.993013 | G17: 4.764353 | H17: 22.370852 | I17: =IF(C17=0,0,H17/C17) -> 0.11348191 | J17: 30 | K17: 9.6407095 | L17: 0 | M17: 30.840366 | N17: 0 | O17: 89.17644 | P17: 72 | Q17: 85.349877 | R17: 0.45165917 | S17: watch | T17: no | V17: Consumer + AI | W17: =SUMIFS($C$5:$C$116,$A$5:$A$116,$V17,$B$5:$B$116,1) -> 200.17583 | X17: =SUMIFS($C$5:$C$116,$A$5:$A$116,$V17,$B$5:$B$116,2) -> 199.55381 | Y17: =SUMIFS($C$5:$C$116,$A$5:$A$116,$V17,$B$5:$B$116,3) -> 201.1182 | Z17: =SUMIFS($C$5:$C$116,$A$5:$A$116,$V17,$B$5:$B$116,4) -> 206.09479 | AA17: =SUMIFS($C$5:$C$116,$A$5:$A$116,$V17,$B$5:$B$116,5) -> 214.11044 | AB17: =SUMIFS($C$5:$C$116,$A$5:$A$116,$V17,$B$5:$B$116,6) -> 221.42378 | AC17: =SUMIFS($C$5:$C$116,$A$5:$A$116,$V17,$B$5:$B$116,7) -> 228.92571 | AD17: =SUMIFS($C$5:$C$116,$A$5:$A$116,$V17,$B$5:$B$116,8) -> 241.53032
... A19: Enterprise-led | B19: 7 | C19: 196.09153 | D19: 128.60297 | E19: 46.733312 | F19: 15.93634 | G19: 4.8189065 | H19: 21.199805 | I19: =IF(C19=0,0,H19/C19) -> 0.10811178 | J19: 23.924984 | K19: 1.4966348 | L19: 0.030112156 | M19: 25 | N19: 0.030112156 | O19: 76.278738 | P19: 64 | Q19: 84.253191 | R19: 0.28708162 | S19: watch | T19: no | V19: Enterprise + AI + People | W19: =SUMIFS($C$5:$C$116,$A$5:$A$116,$V19,$B$5:$B$116,1) -> 200.02783 | X19: =SUMIFS($C$5:$C$116,$A$5:$A$116,$V19,$B$5:$B$116,2) -> 198.85439 | Y19: =SUMIFS($C$5:$C$116,$A$5:$A$116,$V19,$B$5:$B$116,3) -> 199.15544 | Z19: =SUMIFS($C$5:$C$116,$A$5:$A$116,$V19,$B$5:$B$116,4) -> 201.68521 | AA19: =SUMIFS($C$5:$C$116,$A$5:$A$116,$V19,$B$5:$B$116,5) -> 206.34055 | AB19: =SUMIFS($C$5:$C$116,$A$5:$A$116,$V19,$B$5:$B$116,6) -> 212.74417 | AC19: =SUMIFS($C$5:$C$116,$A$5:$A$116,$V19,$B$5:$B$116,7) -> 222.13238 | AD19: =SUMIFS($C$5:$C$116,$A$5:$A$116,$V19,$B$5:$B$116,8) -> 233.40985
A20: Enterprise-led | B20: 8 | C20: 197.52408 | D20: 126.61435 | E20: 50.102165 | F20: 15.889402 | G20: 4.9181626 | H20: 23.305665 | I20: =IF(C20=0,0,H20/C20) -> 0.11798898 | J20: 23.18414 | K20: 0.15727871 | L20: 0.035753278 | M20: 25 | N20: 0.065865433 | O20: 81.785813 | P20: 63 | Q20: 86.030822 | R20: 0.20121258 | S20: watch | T20: no
A21: AI-led | B21: 1 | C21: 200.06993 | D21: 140.04516 | E21: 40 | F21: 15.99968 | G21: 4.0250948 | H21: 30.054717 | I21: =IF(C21=0,0,H21/C21) -> 0.15022106 | J21: 30 | K21: 0 | L21: 0 | M21: 60.054717 | N21: 0 | O21: 100.13259 | P21: 72 | Q21: 62.85 | R21: 0.47732697 | S21: healthy | T21: no | V21: Operating profit ($M)
A22: AI-led | B22: 2 | C22: 199.73857 | D22: 138.47553 | E22: 40.000633 | F22: 15.998792 | G22: 5.2636148 | H22: 28.764069 | I22: =IF(C22=0,0,H22/C22) -> 0.14400859 | J22: 30 | K22: 0 | L22: 0 | M22: 58.818786 | N22: 0 | O22: 99.867395 | P22: 72 | Q22: 67.712005 | R22: 0.4430529 | S22: healthy | T22: no | V22: Strategy | W22: Q1 | X22: Q2 | Y22: Q3 | Z22: Q4 | AA22: Q5 | AB22: Q6 | AC22: Q7 | AD22: Q8
A23: AI-led | B23: 3 | C23: 202.03069 | D23: 137.89068 | E23: 40.007932 | F23: 15.997945 | G23: 8.1341347 | H23: 28.655462 | I23: =IF(C23=0,0,H23/C23) -> 0.14183718 | J23: 30 | K23: 0 | L23: 0 | M23: 57.474249 | N23: 0 | O23: 107.34052 | P23: 72 | Q23: 73.466618 | R23: 0.40834873 | S23: healthy | T23: no | V23: Consumer-led | W23: =SUMIFS($H$5:$H$116,$A$5:$A$116,$V23,$B$5:$B$116,1) -> 30.215882 | X23: =SUMIFS($H$5:$H$116,$A$5:$A$116,$V23,$B$5:$B$116,2) -> 29.693849 | Y23: =SUMIFS($H$5:$H$116,$A$5:$A$116,$V23,$B$5:$B$116,3) -> 28.946941 | Z23: =SUMIFS($H$5:$H$116,$A$5:$A$116,$V23,$B$5:$B$116,4) -> 29.501711 | AA23: =SUMIFS($H$5:$H$116,$A$5:$A$116,$V23,$B$5:$B$116,5) -> 31.444173 | AB23: =SUMIFS($H$5:$H$116,$A$5:$A$116,$V23,$B$5:$B$116,6) -> 33.507525 | AC23: =SUMIFS($H$5:$H$116,$A$5:$A$116,$V23,$B$5:$B$116,7) -> 32.112579 | AD23: =SUMIFS($H$5:$H$116,$A$5:$A$116,$V23,$B$5:$B$116,8) -> 34.530189
A24: AI-led | B24: 4 | C24: 207.59878 | D24: 138.40374 | E24: 40.051696 | F24: 15.996736 | G24: 13.14661 | H24: 31.287224 | I24: =IF(C24=0,0,H24/C24) -> 0.15071006 | J24: 30 | K24: 0 | L24: 0 | M24: 58.761473 | N24: 0 | O24: 119.21099 | P24: 72 | Q24: 79.223503 | R24: 0.43660668 | S24: healthy | T24: no | V24: Enterprise-led | W24: =SUMIFS($H$5:$H$116,$A$5:$A$116,$V24,$B$5:$B$116,1) -> 30.05901 | X24: =SUMIFS($H$5:$H$116,$A$5:$A$116,$V24,$B$5:$B$116,2) -> 28.298153 | Y24: =SUMIFS($H$5:$H$116,$A$5:$A$116,$V24,$B$5:$B$116,3) -> 25.852616 | Z24: =SUMIFS($H$5:$H$116,$A$5:$A$116,$V24,$B$5:$B$116,4) -> 23.900445 | AA24: =SUMIFS($H$5:$H$116,$A$5:$A$116,$V24,$B$5:$B$116,5) -> 22.370852 | AB24: =SUMIFS($H$5:$H$116,$A$5:$A$116,$V24,$B$5:$B$116,6) -> 24.845554 | AC24: =SUMIFS($H$5:$H$116,$A$5:$A$116,$V24,$B$5:$B$116,7) -> 21.199805 | AD24: =SUMIFS($H$5:$H$116,$A$5:$A$116,$V24,$B$5:$B$116,8) -> 23.305665
A25: AI-led | B25: 5 | C25: 215.29644 | D25: 139.74438 | E25: 40.138447 | F25: 15.993013 | G25: 19.420601 | H25: 35.426008 | I25: =IF(C25=0,0,H25/C25) -> 0.16454526 | J25: 30 | K25: 0 | L25: 0 | M25: 64.187482 | N25: 0 | O25: 131.38709 | P25: 72 | Q25: 85.015274 | R25: 0.3868659 | S25: healthy | T25: no | V25: AI-led | W25: =SUMIFS($H$5:$H$116,$A$5:$A$116,$V25,$B$5:$B$116,1) -> 30.054717 | X25: =SUMIFS($H$5:$H$116,$A$5:$A$116,$V25,$B$5:$B$116,2) -> 28.764069 | Y25: =SUMIFS($H$5:$H$116,$A$5:$A$116,$V25,$B$5:$B$116,3) -> 28.655462 | Z25: =SUMIFS($H$5:$H$116,$A$5:$A$116,$V25,$B$5:$B$116,4) -> 31.287224 | AA25: =SUMIFS($H$5:$H$116,$A$5:$A$116,$V25,$B$5:$B$116,5) -> 35.426008 | AB25: =SUMIFS($H$5:$H$116,$A$5:$A$116,$V25,$B$5:$B$116,6) -> 38.654433 | AC25: =SUMIFS($H$5:$H$116,$A$5:$A$116,$V25,$B$5:$B$116,7) -> 39.289588 | AD25: =SUMIFS($H$5:$H$116,$A$5:$A$116,$V25,$B$5:$B$116,8) -> 45.626067
A26: AI-led | B26: 6 | C26: 220.84267 | D26: 139.73842 | E26: 40.040839 | F26: 15.973898 | G26: 25.089508 | H26: 38.654433 | I26: =IF(C26=0,0,H26/C26) -> 0.17503154 | J26: 30 | K26: 0 | L26: 0 | M26: 72.841914 | N26: 0 | O26: 135.12215 | P26: 72 | Q26: 90.866235 | R26: 0.34324643 | S26: healthy | T26: no | V26: Diversified | W26: =SUMIFS($H$5:$H$116,$A$5:$A$116,$V26,$B$5:$B$116,1) -> 30.1117 | X26: =SUMIFS($H$5:$H$116,$A$5:$A$116,$V26,$B$5:$B$116,2) -> 29.067783 | Y26: =SUMIFS($H$5:$H$116,$A$5:$A$116,$V26,$B$5:$B$116,3) -> 28.324262 | Z26: =SUMIFS($H$5:$H$116,$A$5:$A$116,$V26,$B$5:$B$116,4) -> 29.61444 | AA26: =SUMIFS($H$5:$H$116,$A$5:$A$116,$V26,$B$5:$B$116,5) -> 32.611535 | AB26: =SUMIFS($H$5:$H$116,$A$5:$A$116,$V26,$B$5:$B$116,6) -> 37.527177 | AC26: =SUMIFS($H$5:$H$116,$A$5:$A$116,$V26,$B$5:$B$116,7) -> 39.79674 | AD26: =SUMIFS($H$5:$H$116,$A$5:$A$116,$V26,$B$5:$B$116,8) -> 46.040358
A27: AI-led | B27: 7 | C27: 224.97777 | D27: 138.14459 | E27: 39.22803 | F27: 15.94785 | G27: 31.657299 | H27: 39.289588 | I27: =IF(C27=0,0,H27/C27) -> 0.17463764 | J27: 30 | K27: 2 | L27: 0 | M27: 80.131502 | N27: 0 | O27: 134.98332 | P27: 67.705829 | Q27: 92.783134 | R27: 0.31471237 | S27: healthy | T27: no | V27: Consumer-only | W27: =SUMIFS($H$5:$H$116,$A$5:$A$116,$V27,$B$5:$B$116,1) -> 30.201781 | X27: =SUMIFS($H$5:$H$116,$A$5:$A$116,$V27,$B$5:$B$116,2) -> 30.156762 | Y27: =SUMIFS($H$5:$H$116,$A$5:$A$116,$V27,$B$5:$B$116,3) -> 29.777154 | Z27: =SUMIFS($H$5:$H$116,$A$5:$A$116,$V27,$B$5:$B$116,4) -> 30.606775 | AA27: =SUMIFS($H$5:$H$116,$A$5:$A$116,$V27,$B$5:$B$116,5) -> 32.385685 | AB27: =SUMIFS($H$5:$H$116,$A$5:$A$116,$V27,$B$5:$B$116,6) -> 35.791929 | AC27: =SUMIFS($H$5:$H$116,$A$5:$A$116,$V27,$B$5:$B$116,7) -> 33.409712 | AD27: =SUMIFS($H$5:$H$116,$A$5:$A$116,$V27,$B$5:$B$116,8) -> 34.747534
A28: AI-led | B28: 8 | C28: 234.70009 | D28: 140.15309 | E28: 39.370979 | F28: 15.922167 | G28: 39.253856 | H28: 45.626067 | I28: =IF(C28=0,0,H28/C28) -> 0.19440157 | J28: 41.25 | K28: 0 | L28: 0 | M28: 84.507569 | N28: 0 | O28: 148.51302 | P28: 67.705829 | Q28: 100 | R28: 0.289 | S28: healthy | T28: no | V28: Enterprise-only | W28: =SUMIFS($H$5:$H$116,$A$5:$A$116,$V28,$B$5:$B$116,1) -> 30.018163 | X28: =SUMIFS($H$5:$H$116,$A$5:$A$116,$V28,$B$5:$B$116,2) -> 28.268054 | Y28: =SUMIFS($H$5:$H$116,$A$5:$A$116,$V28,$B$5:$B$116,3) -> 25.666744 | Z28: =SUMIFS($H$5:$H$116,$A$5:$A$116,$V28,$B$5:$B$116,4) -> 23.397288 | AA28: =SUMIFS($H$5:$H$116,$A$5:$A$116,$V28,$B$5:$B$116,5) -> 21.425138 | AB28: =SUMIFS($H$5:$H$116,$A$5:$A$116,$V28,$B$5:$B$116,6) -> 25.258734 | AC28: =SUMIFS($H$5:$H$116,$A$5:$A$116,$V28,$B$5:$B$116,7) -> 20.565899 | AD28: =SUMIFS($H$5:$H$116,$A$5:$A$116,$V28,$B$5:$B$116,8) -> 22.33508
A29: Diversified | B29: 1 | C29: 200.14854 | D29: 140.13031 | E29: 40.017833 | F29: 15.99968 | G29: 4.0007133 | H29: 30.1117 | I29: =IF(C29=0,0,H29/C29) -> 0.15044676 | J29: 30 | K29: 0 | L29: 0 | M29: 60.1117 | N29: 0 | O29: 100.37877 | P29: 72 | Q29: 60 | R29: 0.61666667 | S29: healthy | T29: no | V29: AI-only | W29: =SUMIFS($H$5:$H$116,$A$5:$A$116,$V29,$B$5:$B$116,1) -> 30.016835 | X29: =SUMIFS($H$5:$H$116,$A$5:$A$116,$V29,$B$5:$B$116,2) -> 28.725131 | Y29: =SUMIFS($H$5:$H$116,$A$5:$A$116,$V29,$B$5:$B$116,3) -> 28.277115 | Z29: =SUMIFS($H$5:$H$116,$A$5:$A$116,$V29,$B$5:$B$116,4) -> 29.765741 | AA29: =SUMIFS($H$5:$H$116,$A$5:$A$116,$V29,$B$5:$B$116,5) -> 32.25307 | AB29: =SUMIFS($H$5:$H$116,$A$5:$A$116,$V29,$B$5:$B$116,6) -> 35.665351 | AC29: =SUMIFS($H$5:$H$116,$A$5:$A$116,$V29,$B$5:$B$116,7) -> 34.563491 | AD29: =SUMIFS($H$5:$H$116,$A$5:$A$116,$V29,$B$5:$B$116,8) -> 38.982539
A30: Diversified | B30: 2 | C30: 199.16879 | D30: 138.5111 | E30: 40.085695 | F30: 15.998792 | G30: 4.573204 | H30: 29.067783 | I30: =IF(C30=0,0,H30/C30) -> 0.14594548 | J30: 30 | K30: 0 | L30: 0 | M30: 59.179483 | N30: 0 | O30: 99.14872 | P30: 72 | Q30: 60 | R30: 0.61666667 | S30: healthy | T30: no | V30: University-led | W30: =SUMIFS($H$5:$H$116,$A$5:$A$116,$V30,$B$5:$B$116,1) -> 30.047579 | X30: =SUMIFS($H$5:$H$116,$A$5:$A$116,$V30,$B$5:$B$116,2) -> 29.060567 | Y30: =SUMIFS($H$5:$H$116,$A$5:$A$116,$V30,$B$5:$B$116,3) -> 27.452077 | Z30: =SUMIFS($H$5:$H$116,$A$5:$A$116,$V30,$B$5:$B$116,4) -> 26.528025 | AA30: =SUMIFS($H$5:$H$116,$A$5:$A$116,$V30,$B$5:$B$116,5) -> 26.286722 | AB30: =SUMIFS($H$5:$H$116,$A$5:$A$116,$V30,$B$5:$B$116,6) -> 25.996002 | AC30: =SUMIFS($H$5:$H$116,$A$5:$A$116,$V30,$B$5:$B$116,7) -> 23.937857 | AD30: =SUMIFS($H$5:$H$116,$A$5:$A$116,$V30,$B$5:$B$116,8) -> 24.703897
A31: Diversified | B31: 3 | C31: 199.76185 | D31: 137.75436 | E31: 40.233503 | F31: 15.997945 | G31: 5.776035 | H31: 28.324262 | I31: =IF(C31=0,0,H31/C31) -> 0.14179015 | J31: 30 | K31: 0 | L31: 0 | M31: 57.503745 | N31: 0 | O31: 103.21868 | P31: 72 | Q31: 60 | R31: 0.61666667 | S31: healthy | T31: no | V31: Cash preservation | W31: =SUMIFS($H$5:$H$116,$A$5:$A$116,$V31,$B$5:$B$116,1) -> 30.041117 | X31: =SUMIFS($H$5:$H$116,$A$5:$A$116,$V31,$B$5:$B$116,2) -> 29.237487 | Y31: =SUMIFS($H$5:$H$116,$A$5:$A$116,$V31,$B$5:$B$116,3) -> 27.743483 | Z31: =SUMIFS($H$5:$H$116,$A$5:$A$116,$V31,$B$5:$B$116,4) -> 26.878731 | AA31: =SUMIFS($H$5:$H$116,$A$5:$A$116,$V31,$B$5:$B$116,5) -> 26.660549 | AB31: =SUMIFS($H$5:$H$116,$A$5:$A$116,$V31,$B$5:$B$116,6) -> 27.917646 | AC31: =SUMIFS($H$5:$H$116,$A$5:$A$116,$V31,$B$5:$B$116,7) -> 26.584109 | AD31: =SUMIFS($H$5:$H$116,$A$5:$A$116,$V31,$B$5:$B$116,8) -> 28.102658
A32: Diversified | B32: 4 | C32: 202.6907 | D32: 138.0142 | E32: 40.512554 | F32: 15.996736 | G32: 8.1672066 | H32: 29.61444 | I32: =IF(C32=0,0,H32/C32) -> 0.14610656 | J32: 30 | K32: 0 | L32: 0 | M32: 57.118185 | N32: 0 | O32: 109.93568 | P32: 72 | Q32: 60 | R32: 0.70775495 | S32: healthy | T32: no | V32: Adaptive (evidence-responsive) | W32: =SUMIFS($H$5:$H$116,$A$5:$A$116,$V32,$B$5:$B$116,1) -> 30.074246 | X32: =SUMIFS($H$5:$H$116,$A$5:$A$116,$V32,$B$5:$B$116,2) -> 29.081194 | Y32: =SUMIFS($H$5:$H$116,$A$5:$A$116,$V32,$B$5:$B$116,3) -> 27.57945 | Z32: =SUMIFS($H$5:$H$116,$A$5:$A$116,$V32,$B$5:$B$116,4) -> 27.94324 | AA32: =SUMIFS($H$5:$H$116,$A$5:$A$116,$V32,$B$5:$B$116,5) -> 30.449025 | AB32: =SUMIFS($H$5:$H$116,$A$5:$A$116,$V32,$B$5:$B$116,6) -> 32.593425 | AC32: =SUMIFS($H$5:$H$116,$A$5:$A$116,$V32,$B$5:$B$116,7) -> 37.350486 | AD32: =SUMIFS($H$5:$H$116,$A$5:$A$116,$V32,$B$5:$B$116,8) -> 47.053928
A33: Diversified | B33: 5 | C33: 207.92077 | D33: 139.33709 | E33: 40.993322 | F33: 15.993013 | G33: 11.597347 | H33: 32.611535 | I33: =IF(C33=0,0,H33/C33) -> 0.15684597 | J33: 30 | K33: 0 | L33: 0 | M33: 59.72972 | N33: 0 | O33: 119.50045 | P33: 72 | Q33: 60 | R33: 0.70775495 | S33: healthy | T33: no | V33: University-only | W33: =SUMIFS($H$5:$H$116,$A$5:$A$116,$V33,$B$5:$B$116,1) -> 29.997419 | X33: =SUMIFS($H$5:$H$116,$A$5:$A$116,$V33,$B$5:$B$116,2) -> 29.386161 | Y33: =SUMIFS($H$5:$H$116,$A$5:$A$116,$V33,$B$5:$B$116,3) -> 27.951445 | Z33: =SUMIFS($H$5:$H$116,$A$5:$A$116,$V33,$B$5:$B$116,4) -> 27.012943 | AA33: =SUMIFS($H$5:$H$116,$A$5:$A$116,$V33,$B$5:$B$116,5) -> 26.595442 | AB33: =SUMIFS($H$5:$H$116,$A$5:$A$116,$V33,$B$5:$B$116,6) -> 27.745563 | AC33: =SUMIFS($H$5:$H$116,$A$5:$A$116,$V33,$B$5:$B$116,7) -> 25.083006 | AD33: =SUMIFS($H$5:$H$116,$A$5:$A$116,$V33,$B$5:$B$116,8) -> 25.150063
A34: Diversified | B34: 6 | C34: 211.85648 | D34: 139.32885 | E34: 41.555803 | F34: 15.973898 | G34: 14.997934 | H34: 37.527177 | I34: =IF(C34=0,0,H34/C34) -> 0.1771349 | J34: 30 | K34: 0 | L34: 0 | M34: 67.256897 | N34: 0 | O34: 124.7436 | P34: 70.5 | Q34: 59 | R34: 0.71975079 | S34: healthy | T34: no | V34: Consumer + AI | W34: =SUMIFS($H$5:$H$116,$A$5:$A$116,$V34,$B$5:$B$116,1) -> 30.131077 | X34: =SUMIFS($H$5:$H$116,$A$5:$A$116,$V34,$B$5:$B$116,2) -> 29.472986 | Y34: =SUMIFS($H$5:$H$116,$A$5:$A$116,$V34,$B$5:$B$116,3) -> 29.608923 | Z34: =SUMIFS($H$5:$H$116,$A$5:$A$116,$V34,$B$5:$B$116,4) -> 32.578589 | AA34: =SUMIFS($H$5:$H$116,$A$5:$A$116,$V34,$B$5:$B$116,5) -> 37.734804 | AB34: =SUMIFS($H$5:$H$116,$A$5:$A$116,$V34,$B$5:$B$116,6) -> 45.443239 | AC34: =SUMIFS($H$5:$H$116,$A$5:$A$116,$V34,$B$5:$B$116,7) -> 49.251677 | AD34: =SUMIFS($H$5:$H$116,$A$5:$A$116,$V34,$B$5:$B$116,8) -> 57.949347
... A36: Diversified | B36: 8 | C36: 226.21999 | D36: 141.87752 | E36: 43.797326 | F36: 15.922167 | G36: 24.622982 | H36: 46.040358 | I36: =IF(C36=0,0,H36/C36) -> 0.20352029 | J36: 40.555556 | K36: 0 | L36: 0 | M36: 76.420295 | N36: 0 | O36: 143.75331 | P36: 69.451645 | Q36: 59.90329 | R36: 0.77439634 | S36: healthy | T36: no | V36: Enterprise + AI + People | W36: =SUMIFS($H$5:$H$116,$A$5:$A$116,$V36,$B$5:$B$116,1) -> 30.022385 | X36: =SUMIFS($H$5:$H$116,$A$5:$A$116,$V36,$B$5:$B$116,2) -> 28.348261 | Y36: =SUMIFS($H$5:$H$116,$A$5:$A$116,$V36,$B$5:$B$116,3) -> 26.909004 | Z36: =SUMIFS($H$5:$H$116,$A$5:$A$116,$V36,$B$5:$B$116,4) -> 27.446792 | AA36: =SUMIFS($H$5:$H$116,$A$5:$A$116,$V36,$B$5:$B$116,5) -> 29.619542 | AB36: =SUMIFS($H$5:$H$116,$A$5:$A$116,$V36,$B$5:$B$116,6) -> 31.037599 | AC36: =SUMIFS($H$5:$H$116,$A$5:$A$116,$V36,$B$5:$B$116,7) -> 35.007985 | AD36: =SUMIFS($H$5:$H$116,$A$5:$A$116,$V36,$B$5:$B$116,8) -> 44.191944
A37: Consumer-only | B37: 1 | C37: 200.27087 | D37: 140.27119 | E37: 40 | F37: 15.99968 | G37: 4 | H37: 30.201781 | I37: =IF(C37=0,0,H37/C37) -> 0.15080466 | J37: 30 | K37: 0 | L37: 0 | M37: 60.201781 | N37: 0 | O37: 100.65677 | P37: 72 | Q37: 60 | R37: 0.46666667 | S37: healthy | T37: no
A38: Consumer-only | B38: 2 | C38: 199.34345 | D38: 139.06488 | E38: 39.99978 | F38: 15.998792 | G38: 4.28 | H38: 30.156762 | I38: =IF(C38=0,0,H38/C38) -> 0.15128042 | J38: 30 | K38: 0 | L38: 0 | M38: 60.358542 | N38: 0 | O38: 100.09447 | P38: 72 | Q38: 60 | R38: 0.46666667 | S38: healthy | T38: no | V38: Cash ($M)
A39: Consumer-only | B39: 3 | C39: 199.23324 | D39: 138.80566 | E39: 39.998746 | F39: 15.997945 | G39: 4.4308877 | H39: 29.777154 | I39: =IF(C39=0,0,H39/C39) -> 0.14945877 | J39: 30 | K39: 0 | L39: 0 | M39: 60.135696 | N39: 0 | O39: 102.82663 | P39: 72 | Q39: 60 | R39: 0.46666667 | S39: healthy | T39: no | V39: Strategy | W39: Q1 | X39: Q2 | Y39: Q3 | Z39: Q4 | AA39: Q5 | AB39: Q6 | AC39: Q7 | AD39: Q8
A40: Consumer-only | B40: 4 | C40: 200.49999 | D40: 139.93158 | E40: 40.005432 | F40: 15.996736 | G40: 4.5662357 | H40: 30.606775 | I40: =IF(C40=0,0,H40/C40) -> 0.15265225 | J40: 30 | K40: 0 | L40: 0 | M40: 60.742471 | N40: 0 | O40: 106.8341 | P40: 72 | Q40: 60 | R40: 0.557875 | S40: healthy | T40: no | V40: Consumer-led | W40: =SUMIFS($M$5:$M$116,$A$5:$A$116,$V40,$B$5:$B$116,1) -> 60.215882 | X40: =SUMIFS($M$5:$M$116,$A$5:$A$116,$V40,$B$5:$B$116,2) -> 59.90973 | Y40: =SUMIFS($M$5:$M$116,$A$5:$A$116,$V40,$B$5:$B$116,3) -> 58.856671 | Z40: =SUMIFS($M$5:$M$116,$A$5:$A$116,$V40,$B$5:$B$116,4) -> 58.358382 | AA40: =SUMIFS($M$5:$M$116,$A$5:$A$116,$V40,$B$5:$B$116,5) -> 59.802555 | AB40: =SUMIFS($M$5:$M$116,$A$5:$A$116,$V40,$B$5:$B$116,6) -> 63.31008 | AC40: =SUMIFS($M$5:$M$116,$A$5:$A$116,$V40,$B$5:$B$116,7) -> 53.366721 | AD40: =SUMIFS($M$5:$M$116,$A$5:$A$116,$V40,$B$5:$B$116,8) -> 46.64691
A41: Consumer-only | B41: 5 | C41: 203.00558 | D41: 142.35838 | E41: 39.994841 | F41: 15.993013 | G41: 4.6593461 | H41: 32.385685 | I41: =IF(C41=0,0,H41/C41) -> 0.15953101 | J41: 30 | K41: 0 | L41: 0 | M41: 63.128157 | N41: 0 | O41: 110.90693 | P41: 72 | Q41: 60 | R41: 0.53454167 | S41: healthy | T41: no | V41: Enterprise-led | W41: =SUMIFS($M$5:$M$116,$A$5:$A$116,$V41,$B$5:$B$116,1) -> 60.05901 | X41: =SUMIFS($M$5:$M$116,$A$5:$A$116,$V41,$B$5:$B$116,2) -> 58.357163 | Y41: =SUMIFS($M$5:$M$116,$A$5:$A$116,$V41,$B$5:$B$116,3) -> 54.209779 | Z41: =SUMIFS($M$5:$M$116,$A$5:$A$116,$V41,$B$5:$B$116,4) -> 48.110224 | AA41: =SUMIFS($M$5:$M$116,$A$5:$A$116,$V41,$B$5:$B$116,5) -> 30.840366 | AB41: =SUMIFS($M$5:$M$116,$A$5:$A$116,$V41,$B$5:$B$116,6) -> 29.191702 | AC41: =SUMIFS($M$5:$M$116,$A$5:$A$116,$V41,$B$5:$B$116,7) -> 25 | AD41: =SUMIFS($M$5:$M$116,$A$5:$A$116,$V41,$B$5:$B$116,8) -> 25
A42: Consumer-only | B42: 6 | C42: 203.93292 | D42: 143.58975 | E42: 39.719983 | F42: 15.973898 | G42: 4.6492861 | H42: 35.791929 | I42: =IF(C42=0,0,H42/C42) -> 0.17550835 | J42: 30 | K42: 0 | L42: 0 | M42: 68.920085 | N42: 0 | O42: 111.71564 | P42: 70.5 | Q42: 59 | R42: 0.51987288 | S42: healthy | T42: no | V42: AI-led | W42: =SUMIFS($M$5:$M$116,$A$5:$A$116,$V42,$B$5:$B$116,1) -> 60.054717 | X42: =SUMIFS($M$5:$M$116,$A$5:$A$116,$V42,$B$5:$B$116,2) -> 58.818786 | Y42: =SUMIFS($M$5:$M$116,$A$5:$A$116,$V42,$B$5:$B$116,3) -> 57.474249 | Z42: =SUMIFS($M$5:$M$116,$A$5:$A$116,$V42,$B$5:$B$116,4) -> 58.761473 | AA42: =SUMIFS($M$5:$M$116,$A$5:$A$116,$V42,$B$5:$B$116,5) -> 64.187482 | AB42: =SUMIFS($M$5:$M$116,$A$5:$A$116,$V42,$B$5:$B$116,6) -> 72.841914 | AC42: =SUMIFS($M$5:$M$116,$A$5:$A$116,$V42,$B$5:$B$116,7) -> 80.131502 | AD42: =SUMIFS($M$5:$M$116,$A$5:$A$116,$V42,$B$5:$B$116,8) -> 84.507569
A43: Consumer-only | B43: 7 | C43: 201.64853 | D43: 141.52523 | E43: 39.484995 | F43: 15.941361 | G43: 4.6969445 | H43: 33.409712 | I43: =IF(C43=0,0,H43/C43) -> 0.16568289 | J43: 30 | K43: 13.185996 | L43: 0 | M43: 59.143801 | N43: 0 | O43: 103.9525 | P43: 70.5 | Q43: 59 | R43: 0.51525424 | S43: healthy | T43: no | V43: Diversified | W43: =SUMIFS($M$5:$M$116,$A$5:$A$116,$V43,$B$5:$B$116,1) -> 60.1117 | X43: =SUMIFS($M$5:$M$116,$A$5:$A$116,$V43,$B$5:$B$116,2) -> 59.179483 | Y43: =SUMIFS($M$5:$M$116,$A$5:$A$116,$V43,$B$5:$B$116,3) -> 57.503745 | Z43: =SUMIFS($M$5:$M$116,$A$5:$A$116,$V43,$B$5:$B$116,4) -> 57.118185 | AA43: =SUMIFS($M$5:$M$116,$A$5:$A$116,$V43,$B$5:$B$116,5) -> 59.72972 | AB43: =SUMIFS($M$5:$M$116,$A$5:$A$116,$V43,$B$5:$B$116,6) -> 67.256897 | AC43: =SUMIFS($M$5:$M$116,$A$5:$A$116,$V43,$B$5:$B$116,7) -> 70.935492 | AD43: =SUMIFS($M$5:$M$116,$A$5:$A$116,$V43,$B$5:$B$116,8) -> 76.420295
...

Sheet Investment & capability
A1: 3 · Investment and capability outcomes
A2: Capabilities built by Q8, the marginal return of each bucket, allocation-grid main effects and the bucket economics that drive them.
A4: A · Capability and organizational state at Q8 (start: Consumer 55, Enterprise 30, AI 10, Talent 55, Credential 40, Culture 72; capability ceiling 120)
A5: Strategy | B5: Consumer | C5: Enterprise | D5: AI | E5: Talent | F5: Credential | G5: Culture | H5: Org capacity | I5: Capability gain | J5: Consumer rev Q8 | K5: Enterprise rev Q8 | L5: University rev Q8 | M5: AI-native rev Q8 | N5: Δ Consumer rev vs Q0 | O5: Δ Enterprise rev vs Q0 | P5: Δ University rev vs Q0 | Q5: Δ AI-native rev vs Q0
A6: Consumer-led | B6: 120 | C6: 30 | D6: 11.042229 | E6: 100 | F6: 40 | G6: 72 | H6: 100 | I6: 111.04223 | J6: 151.88496 | K6: 39.542181 | L6: 15.905861 | M6: 5.0377074 | N6: =J6-140 -> 11.884958 | O6: =K6-40 -> -0.45781896 | P6: =L6-16 -> -0.094139367 | Q6: =M6-4 -> 1.0377074
A7: Enterprise-led | B7: 53 | C7: 120 | D7: 10 | E7: 84.861371 | F7: 40 | G7: 63 | H7: 86.030822 | I7: 137.08348 | J7: 126.61435 | K7: 50.102165 | L7: 15.889402 | M7: 4.9181626 | N7: =J7-140 -> -13.385651 | O7: =K7-40 -> 10.102165 | P7: =L7-16 -> -0.11059788 | Q7: =M7-4 -> 0.91816257
A8: AI-led | B8: 55 | C8: 30 | D8: 100 | E8: 99.075189 | F8: 40 | G8: 67.705829 | H8: 100 | I8: 134.07519 | J8: 140.15309 | K8: 39.370979 | L8: 15.922167 | M8: 39.253856 | N8: =J8-140 -> 0.15309239 | O8: =K8-40 -> -0.62902121 | P8: =L8-16 -> -0.077833229 | Q8: =M8-4 -> 35.253856
A9: Diversified | B9: 100 | C9: 95.94084 | D9: 86.178235 | E9: 53.5 | F9: 40 | G9: 69.451645 | H9: 59.90329 | I9: 194.49002 | J9: 141.87752 | K9: 43.797326 | L9: 15.922167 | M9: 24.622982 | N9: =J9-140 -> 1.8775167 | O9: =K9-40 -> 3.7973264 | P9: =L9-16 -> -0.077833229 | Q9: =M9-4 -> 20.622982
A10: Consumer-only | B10: 120 | C10: 30 | D10: 11.880066 | E10: 53.5 | F10: 40 | G10: 70.5 | H10: 59 | I10: 65.380066 | J10: 143.95298 | K10: 39.246379 | L10: 15.904194 | M10: 4.7896082 | N10: =J10-140 -> 3.9529786 | O10: =K10-40 -> -0.75362131 | P10: =L10-16 -> -0.095805623 | Q10: =M10-4 -> 0.78960818
A11: Enterprise-only | B11: 53 | C11: 120 | D11: 10 | E11: 45.5 | F11: 40 | G11: 61.5 | H11: 53 | I11: 106.25718 | J11: 120.68708 | K11: 51.985268 | L11: 15.888332 | M11: 4.717746 | N11: =J11-140 -> -19.312916 | O11: =K11-40 -> 11.985268 | P11: =L11-16 -> -0.11166822 | Q11: =M11-4 -> 0.71774604
A12: AI-only | B12: 58.230255 | C12: 30 | D12: 120 | E12: 53.5 | F12: 40 | G12: 70.5 | H12: 59 | I12: 111.73026 | J12: 126.57191 | K12: 39.712694 | L12: 15.908185 | M12: 38.751097 | N12: =J12-140 -> -13.428088 | O12: =K12-40 -> -0.28730559 | P12: =L12-16 -> -0.091815307 | Q12: =M12-4 -> 34.751097
A13: University-led | B13: 55 | C13: 30 | D13: 10 | E13: 100 | F13: 120 | G13: 72 | H13: 100 | I13: 125 | J13: 137.39844 | K13: 40.652857 | L13: 15.121688 | M13: 4.9911986 | N13: =J13-140 -> -2.6015564 | O13: =K13-40 -> 0.65285734 | P13: =L13-16 -> -0.87831172 | Q13: =M13-4 -> 0.99119857
A14: Cash preservation | B14: 85.885219 | C14: 55.477039 | D14: 38.649172 | E14: 53.5 | F14: 40 | G14: 69.524057 | H14: 60.048114 | I14: 84.84047 | J14: 129.00819 | K14: 40.775678 | L14: 15.922167 | M14: 10.645756 | N14: =J14-140 -> -10.991806 | O14: =K14-40 -> 0.77567781 | P14: =L14-16 -> -0.077833229 | Q14: =M14-4 -> 6.6457555
A15: Adaptive (evidence-responsive) | B15: 87.711857 | C15: 81.16835 | D15: 61.676565 | E15: 81.169485 | F15: 61.158904 | G15: 72 | H15: 79.627114 | I15: 197.82665 | J15: 142.01742 | K15: 51.660652 | L15: 16.040153 | M15: 23.63101 | N15: =J15-140 -> 2.0174174 | O15: =K15-40 -> 11.660652 | P15: =L15-16 -> 0.040152728 | Q15: =M15-4 -> 19.63101
A16: University-only | B16: 55 | C16: 30 | D16: 10 | E16: 53.5 | F16: 120 | G16: 70.5 | H16: 59 | I16: 78.5 | J16: 130.27857 | K16: 40.557616 | L16: 15.179565 | M16: 4.7577498 | N16: =J16-140 -> -9.7214257 | O16: =K16-40 -> 0.55761642 | P16: =L16-16 -> -0.82043518 | Q16: =M16-4 -> 0.75774983
A17: Consumer + AI | B17: 120 | C17: 30 | D17: 114.87958 | E17: 53.5 | F17: 40 | G17: 70.5 | H17: 59 | I17: 168.37958 | J17: 154.62878 | K17: 39.58206 | L17: 15.908672 | M17: 31.410805 | N17: =J17-140 -> 14.628781 | O17: =K17-40 -> -0.41793955 | P17: =L17-16 -> -0.091327564 | Q17: =M17-4 -> 27.410805
... A19: Enterprise + AI + People | B19: 55 | C19: 120 | D19: 92.277593 | E19: 82.232461 | F19: 40 | G19: 72 | H19: 80.424346 | I19: 224.50146 | J19: 132.04648 | K19: 55.193197 | L19: 15.907361 | M19: 30.262814 | N19: =J19-140 -> -7.953519 | O19: =K19-40 -> 15.193197 | P19: =L19-16 -> -0.092639418 | Q19: =M19-4 -> 26.262814
A21: B · Marginal return of $10M a quarter in each bucket
A22: Base: $3M in each bucket + $15M reserve; one bucket +$10M, reserve −$10M; Balanced Marketplace destination; contract declined; 12 quarters (Q9–Q12 extend the last authored market). Deltas vs the base run.
A23: Starting mix | B23: Bucket | C23: Δ Rev Q2 | D23: Δ Rev Q4 | E23: Δ Rev Q8 | F23: Δ Rev Q12 | G23: Δ Cum OP Q8 | H23: Δ Cum OP Q12 | I23: Δ Net cash Q8 | J23: Δ Price Q4 | K23: Δ Price Q8 | L23: Δ Consumer rev Q8 | M23: Δ Enterprise rev Q8 | N23: Δ University rev Q8 | O23: Δ AI-native rev Q8 | P23: Cum OP Q8 per $80M invested
A24: Baseline (production) | B24: Consumer | C24: 0.46334982 | D24: 2.2009572 | E24: 8.2863839 | F24: 10.463468 | G24: 20.212242 | H24: 45.247773 | I24: -59.958638 | J24: 4.9018674 | K24: 10.898799 | L24: 9.1434231 | M24: -0.11382962 | N24: -0.0094125942 | O24: -0.733797 | P24: =G24/80 -> 0.25265303
A25: Baseline (production) | B25: Enterprise | C25: 0.059485044 | D25: 0.28207311 | E25: 2.0446371 | F25: 5.285008 | G25: -7.3588901 | H25: -7.5747194 | I25: -87.515466 | J25: 1.0107898 | K25: 3.0797019 | L25: -0.75319853 | M25: 3.4743171 | N25: -0.0085495022 | O25: -0.66793191 | P25: =G25/80 -> -0.091986126
A26: Baseline (production) | B26: AI/Product | C26: 0.46247769 | D26: 5.690927 | E26: 25.009457 | F26: 36.783926 | G26: 44.88426 | H26: 126.40712 | I26: -35.322176 | J26: 10.758272 | K26: 30.321122 | L26: 6.2367023 | M26: 0.26345699 | N26: -0.011545213 | O26: 18.520843 | P26: =G26/80 -> 0.56105325
A27: Baseline (production) | B27: People | C27: 0.42675645 | D27: 2.0099529 | E27: 9.7097534 | F27: 22.449122 | G27: 4.621693 | H27: 34.25326 | I27: -74.984693 | J27: 2.7884606 | K27: 11.190685 | L27: 7.2217318 | M27: 0.30598168 | N27: -0.0018962096 | O27: 2.1839361 | P27: =G27/80 -> 0.057771163
A28: Baseline (production) | B28: University | C28: 0.036248703 | D28: 0.43251325 | E28: 3.6390521 | F28: 11.648347 | G28: 6.7103393 | H28: 29.041521 | I28: -73.409837 | J28: 3.0442888 | K28: 11.482374 | L28: 3.276765 | M28: 0.45990373 | N28: 0.40766567 | O28: -0.50528229 | P28: =G28/80 -> 0.083879241
A29: Alt A re-based (proportional) | B29: Consumer | C29: 0.29374163 | D29: 1.2525612 | E29: 3.5938261 | F29: 1.0717631 | G29: 8.801794 | H29: 11.057476 | I29: -71.369086 | J29: 3.5502142 | K29: 5.1371678 | L29: 6.5310165 | M29: -0.17074443 | N29: -0.014707178 | O29: -2.7517388 | P29: =G29/80 -> 0.11002243
A30: Alt A re-based (proportional) | B30: Enterprise | C30: 0.072549301 | D30: 0.27576697 | E30: 2.1553734 | F30: 5.604819 | G30: -8.1288841 | H30: -10.356478 | I30: -88.28546 | J30: 1.2850585 | K30: 3.337456 | L30: -0.53799895 | M30: 5.2114756 | N30: -0.013358597 | O30: -2.5047446 | P30: =G30/80 -> -0.10161105
A31: Alt A re-based (proportional) | B31: AI/Product | C31: 1.5911397 | D31: 16.980517 | E31: 74.285093 | F31: 108.44591 | G31: 165.32603 | H31: 441.10181 | I31: 85.119592 | J31: 25.530605 | K31: 44.939624 | L31: 4.4547873 | M31: 0.39518548 | N31: -0.018039395 | O31: 69.45316 | P31: =G31/80 -> 2.0665754
A32: Alt A re-based (proportional) | B32: People | C32: 0.45012003 | D32: 2.4503404 | E32: 13.80415 | F32: 36.304089 | G32: 11.727488 | H32: 72.278307 | I32: -67.878897 | J32: 3.3745603 | K32: 13.803551 | L32: 5.1583799 | M32: 0.45897252 | N32: -0.0029628275 | O32: 8.1897604 | P32: =G32/80 -> 0.1465936
A33: Alt A re-based (proportional) | B33: University | C33: 0.016620724 | D33: 0.19457156 | E33: 1.772571 | F33: 6.5939915 | G33: 2.6173395 | H33: 12.760033 | I33: -77.502837 | J33: 2.8516994 | K33: 9.517628 | L33: 2.3405464 | M33: 0.6898556 | N33: 0.63697761 | O33: -1.8948086 | P33: =G33/80 -> 0.032716744
A34: Alt B re-based (proportional) | B34: Consumer | C34: 0.21039299 | D34: 0.79106096 | E34: 1.3389777 | F34: -3.3762896 | G34: 3.8929881 | H34: -4.2192074 | I34: -76.277892 | J34: 2.9418062 | K34: 3.1635853 | L34: 5.2248132 | M34: -0.19920183 | N34: -0.017648614 | O34: -3.668985 | P34: =G34/80 -> 0.048662352
A35: Alt B re-based (proportional) | B35: Enterprise | C35: 0.080402025 | D35: 0.28412617 | E35: 2.2939658 | F35: 5.9897205 | G35: -8.2202801 | H35: -10.786389 | I35: -88.376856 | J35: 1.4390783 | K35: 2.6968267 | L35: -0.43039916 | M35: 6.0800548 | N35: -0.016030317 | O35: -3.3396595 | P35: =G35/80 -> -0.1027535
... A48: Alt B re-based (AI reward fixed) | B48: University | C48: 0.036475896 | D48: 0.33856336 | E48: 2.7809991 | F48: 9.3678093 | G48: 4.7646777 | H48: 21.720737 | I48: -75.355498 | J48: 3.1481836 | K48: 10.420759 | L48: 1.8724371 | M48: 0.80483153 | N48: 0.76437313 | O48: -0.66064274 | P48: =G48/80 -> 0.059558472
A50: C · Allocation-grid main effects (AVERAGEIFS over the Allocation grid, best destination per allocation)
A51: Average Q8 outcome of all allocations that put the given amount in the bucket. Reads as: how much does a bucket help on average, whatever else is funded.
A52: Mean Q8 share price ($) | B52: $0M | C52: $5M | D52: $10M | E52: $15M | F52: $20M | G52: $25M | H52: $30M
A53: Consumer | B53: =AVERAGEIFS('Allocation grid'!$N$5:$N$2314,'Allocation grid'!$A$5:$A$2314,0,'Allocation grid'!$S$5:$S$2314,1) -> 121.0951 | C53: =AVERAGEIFS('Allocation grid'!$N$5:$N$2314,'Allocation grid'!$A$5:$A$2314,5,'Allocation grid'!$S$5:$S$2314,1) -> 129.93681 | D53: =AVERAGEIFS('Allocation grid'!$N$5:$N$2314,'Allocation grid'!$A$5:$A$2314,10,'Allocation grid'!$S$5:$S$2314,1) -> 133.56589 | E53: =AVERAGEIFS('Allocation grid'!$N$5:$N$2314,'Allocation grid'!$A$5:$A$2314,15,'Allocation grid'!$S$5:$S$2314,1) -> 130.95957 | F53: =AVERAGEIFS('Allocation grid'!$N$5:$N$2314,'Allocation grid'!$A$5:$A$2314,20,'Allocation grid'!$S$5:$S$2314,1) -> 126.80673 | G53: =AVERAGEIFS('Allocation grid'!$N$5:$N$2314,'Allocation grid'!$A$5:$A$2314,25,'Allocation grid'!$S$5:$S$2314,1) -> 118.76919 | H53: =AVERAGEIFS('Allocation grid'!$N$5:$N$2314,'Allocation grid'!$A$5:$A$2314,30,'Allocation grid'!$S$5:$S$2314,1) -> 109.88221
A54: Enterprise | B54: =AVERAGEIFS('Allocation grid'!$N$5:$N$2314,'Allocation grid'!$B$5:$B$2314,0,'Allocation grid'!$S$5:$S$2314,1) -> 130.49344 | C54: =AVERAGEIFS('Allocation grid'!$N$5:$N$2314,'Allocation grid'!$B$5:$B$2314,5,'Allocation grid'!$S$5:$S$2314,1) -> 127.02758 | D54: =AVERAGEIFS('Allocation grid'!$N$5:$N$2314,'Allocation grid'!$B$5:$B$2314,10,'Allocation grid'!$S$5:$S$2314,1) -> 124.23204 | E54: =AVERAGEIFS('Allocation grid'!$N$5:$N$2314,'Allocation grid'!$B$5:$B$2314,15,'Allocation grid'!$S$5:$S$2314,1) -> 116.45127 | F54: =AVERAGEIFS('Allocation grid'!$N$5:$N$2314,'Allocation grid'!$B$5:$B$2314,20,'Allocation grid'!$S$5:$S$2314,1) -> 107.7519 | G54: =AVERAGEIFS('Allocation grid'!$N$5:$N$2314,'Allocation grid'!$B$5:$B$2314,25,'Allocation grid'!$S$5:$S$2314,1) -> 91.883098 | H54: =AVERAGEIFS('Allocation grid'!$N$5:$N$2314,'Allocation grid'!$B$5:$B$2314,30,'Allocation grid'!$S$5:$S$2314,1) -> 84.20773
